from django.core.exceptions import ValidationError
from django.test import TestCase

from utils.for_tests.base_for_authentication import (  # noqa E501
    register_user,
    register_user_profile,
)


class TestModelUserProfile(TestCase):
    def setUp(self):
        self.user = register_user()
        self.profile = register_user_profile(self.user)

        return super().setUp()

    def test_if_profile_returns_correct_name(self):
        completed_sentence = 'Test - 04887398026'

        self.assertEqual(str(self.profile), completed_sentence)

    def test_if_cpf_is_not_valid(self):
        self.profile.cpf = '12345678901'

        with self.assertRaises(ValidationError) as cm:
            self.profile.full_clean()

        self.assertIn('CPF inv√°lido.', str(cm.exception))

    def test_if_cpf_is_valid(self):
        self.profile.full_clean()
